Workbook

Sheet Panduan Cara Pakai
B1: Saran/ Kendala: WA Admin (085156685865)
B2: CARA PAKAI - WAJIB BACA
B4: Step 1
B5: 1. Klik File -> Make a Copy | F5: 1. Klik Titik Tiga -> Share & Export -> Make a Copy
B6: 2. Buka File yang baru di copy | F6: 2. Buka File yang baru di copy
B7: Desktop | F7: Kalau Di HP
B33: Step 2
B34: Terdapat 4 halaman di dalam file google sheet ini, tapi yang akan sering dipakai adalah Kalkulator Biaya Layanan
B38: Di Tabel Pertama, fokus di kolom berwarna hijau:
B39: 1. Harga Produk (WAJIB)
B40: 2-4. Kalau kamu membuat diskon penjual/ voucher, boleh diisi (opsional)
B41: *diskon penjual dll. perlu dikurangi sebelum biaya admin dihitung, karena nanti hasilnya akan berbeda
B53: Di Tabel Kedua, fokus di kolom berwarna hijau:
B54: 1.Gratis Ongkir Xtra : klik dua kali di pilihan, kemudian ketik kategori kamu, kalau di HP pilih logo keyboard (lihat foto)
B55: 2. Promo Xtra. : klik dua kali di pilihan, kemudian pilih ikut/ tidak ikut)
B56: 3. Biaya Administrasi & Biaya Layanan per Kategori: klik dua kali di pilihan, kemudian ketik kategori kamu, kalau di HP pilih logo keyboard (lihat foto)
B57: 4. Fokus di baris warna kuning, sesuaikan dengan status toko kamu sudah star seller/ belum
J60: *Kalo kategori ga ketemu, buka halaman Biaya Layanan Gratis Ongkir Xtra, lalu CTRL + F dan ketik keyword produk kamu. cth: Baju/ Pakaian/ Fashion
J65: *Kalo kategori ga ketemu, buka halaman Biaya Layanan, lalu CTRL + F dan ketik keyword produk kamu. cth: Baju/ Pakaian/ Fashion
B72: Step 3: Tabel Ragkuman
B73: Singkatnya, tabel dibawah ini merupakan rangkuman dari masing" kategori, biaya administrasi dan tipe penjual
B74: namun belum ada produk per kategorinya, maka dari itu kita akan langsung hitung di kalkulatornya yang otomatis ada produk
B75: JENIS BIAYA PENJUAL | C75: TIPE PENJUAL
C76: STAR/STAR+ SELLER ATAU TOTAL PESANAN SELESAI >50 ATAU >6 BULAN SEJAK PRODUK PERTAMA DI UPLOAD
B78: Biaya Administrasi Star/ Star+ | C78: 10.00%4/9,50%/9.00%/8.25%/6.75%/6.50%/5.25%/4.25%/2.50% (sesuai kategori produk)
B79: Biaya Layanan Gratis Ongkir XTRA | C79: • Total pesanan selesai ≤500 atau ≤6 bulan: GRATIS • Total pesanan selesai >500 atau >6 bulan: 6.00%/5.50%/5.00%/4.50%/4.00%/2.00%/1.50%/0.50%
B80: Biaya Layanan Promo XTRA | C80: 4,5%
B81: Biaya Proses Pesanan | C81: Rp1.250
B82: Biaya Layanan Produk Pre Order | C82: 0.03
B83: Total (Jika bergabung dalam semua program) | C83: 10,50% sampai 23,50% + Rp1.250 (sesuai kategori produk)
B85: CALCULATOR UPDATE | C85: WA Admin untuk pertanyaan atau saran (085156685865)
B86: Gratis Ongkir XTRA | C86: Per 16 Juni 2025, shopee menetapkan biaya layanan per kategori, maks 20ribu
B87: Gratis Ongkir XTRA | C87: Cek Detailnya Disini jika ingin biaya terperinci, gunakan CTRL + F dan search kategori yang kamu jual.
B88: Biaya Layanan XTRA | C88: Per 20 Juli 2025, promosi Biaya Layanan Promo XTRA akan berakhir. Setelah itu, Biaya Layanan Promo XTRA sebesar 2% akan diberlakukan dengan batas maks. Rp20.000 per kuantitas produk. Tapi Shopee masih kasih promo lebih rendah 30% jadi 1.4%
B89: Biaya Layanan XTRA | C89: Namun, Penjual yang telah bergabung dalam program Promo XTRA dan Gratis Ongkir XTRA sebelum 1 Juli 2025 masih akan mendapatkan keuntungan promosi spesial Biaya Layanan Promo XTRA, sebesar 1% dengan batas maks. Rp10.000 hingga 15 September 2025.
B90: 2 Januari 2026 | C90: Sheets akan di update dengan biaya admin terbaru (1/1/2026) pada tanggal 2 Januari 2026 (Jam 19:00)
B91: Promo Xtra+ | C91: Sudah ditambahkan, Promo Xtra+ dikenakan biaya tambahan dari 2% biaya awal Promo Xtra 6.5%
B92: 25 Februari 2026 | C92: Update Biaya Administrasi per Kategori
B93: 2 Mei 2026 | C93: https://seller.shopee.co.id/edu/article/7216
B94: Gratis Ongkir Xtra Ukuran Biasa & Khusus | C94: https://seller.shopee.co.id/edu/article/24877
...

Sheet Biaya Administrasi
A1: Kategori Fashion
A3: KATEGORI | D3: BIAYA ADMINISTRASI NON STAR, STAR/STAR+
A4: Aksesoris Fashion | B4: Aksesoris Rambut | C4: Bando & Bandana, Ikat Rambut, Pita & Scrunchie, Jepitan & Pin Rambut, Rambut Palsu & Extension, Hiasan Kepala, Tiara & Mahkota Bunga, Aksesoris Rambut Lainnya | D4: 9,00% | E4: 0.09
B5: Aksesoris Tambahan | C5: Bros & Pin, Bordir, Liontin, Kancing Manset, Tato Temporer, Sapu Tangan, Aksesoris Tambahan Lainnya | E5: 0.09
B6: Anting | C6: Anting | E6: 0.09
B7: Cincin | C7: Cincin | E7: 0.09
B8: Dasi | C8: Dasi | E8: 0.09
B9: Gelang Kaki | C9: Gelang Kaki | E9: 0.09
B10: Gelang Tangan & Bangle | C10: Gelang Tangan & Bangle | E10: 0.09
B11: Ikat Pinggang | C11: Ikat Pinggang | E11: 0.09
B12: Kacamata & Aksesoris | C12: Kacamata Hitam, Frame & Lensa Kacamata, Tempat Kacamata & Aksesoris, Aksesoris Kacamata Lainnya | E12: 0.09
B13: Kalung | C13: Kalung | E13: 0.09
B14: Sarung Tangan | C14: Sarung Tangan | E14: 0.09
B15: Set & Paket Aksesoris | C15: Set & Paket Aksesoris | E15: 0.09
B16: Syal & Selendang | C16: Syal & Selendang | E16: 0.09
B17: Topi | C17: Topi | E17: 0.09
B18: Aksesoris Tambahan | C18: Masker | D18: 8,25% | E18: 0.0825
B19: Logam Mulia | C19: Platinum & Emas, Perak, Berlian, Permata, Logam Mulia Lainnya | D19: 4,25% | E19: 0.0425
B20: Perhiasan Berharga | C20: Kalung, Gelang Tangan, Cincin, Anting, Gelang Kaki, Liontin, Bros & Pin, Set Perhiasan, Perhiasan Berharga Lainnya | E20: 0.0425
B21: Aksesoris Fashion Lainnya | C21: Aksesoris Fashion Lainnya | D21: 9,00% | E21: 0.09
A22: Fashion Bayi & Anak | B22: Aksesoris Bayi & Anak | C22: Ransel, Tas Selempang & Bahu, Tas Troli, Dompet, Tas & Koper Lainnya, Jam Tangan, Topi, Kacamata, Aksesoris Rambut, Sarung Tangan, Ikat Pinggang, Kaos Kaki, Syal, Alat Penutup Telinga, Aksesoris Bayi & Anak Lainnya, Jas Hujan, Sepatu Boot Hujan, Perlengkapan Hujan Lainnya | D22: 9,00% | E22: 0.09
B23: Pakaian Anak Laki-Laki | C23: Kostum, Pakaian Dalam, Pakaian Tidur, Baju Renang, Kaos, Kaos Polo, Kemeja, Jaket & Coat Reguler, Outerwear Musim Dingin, Rompi, Sweater & Kardigan, Blazer, Hoodie, Outerwear Lainnya, Jeans, Celana, Celana Pendek, Overall, Jas & Setelan, Pakaian Anak Laki-Laki Lainnya, Atasan Lainnya, Bawahan Lainnya | E23: 0.09
B24: Pakaian Anak Perempuan | C24: Kostum, Pakaian Dalam, Baju Tidur, Baju Renang, Kaos, Kaos Polo, Kemeja & Blouse, Jaket & Coat Reguler, Outerwear Musim Dingin, Rompi, Sweater & Kardigan, Blazer, Hoodie, Outerwear Lainnya, Jeans, Celana Panjang, Celana Pendek, Rok, Legging, Romper, Jumpsuit & Overall, Dress, Jas & Setelan, Pakaian Anak Perempuan Lainnya, Atasan Lainnya, Bawahan Lainnya | E24: 0.09
B25: Pakaian Bayi | C25: Outerwear Reguler, Outerwear Musim Dingin, Dress, Celana Panjang & Legging, Celana Pendek, Rok, Bawahan Lainnya, Baju Tidur, Atasan, Bodysuit & Jumper, Set, Baju Renang, Pakaian Bayi Lainnya | E25: 0.09
B26: Sepatu Anak Laki-Laki | C26: Sepatu Boot, Sandal, Sepatu Sneaker, Flip Flop, Sepatu Formal, Loafers, Sepatu Anak Laki-Laki Lainnya | E26: 0.09
B27: Sepatu Anak Perempuan | C27: Sepatu Boot, Sandal, Sepatu Sneaker, Loafers, Flip Flop, Flats, Sepatu Anak Perempuan Lainnya | E27: 0.09
B28: Sepatu Bayi | C28: Sepatu Bayi | E28: 0.09
B29: Aksesoris Bayi & Anak | D29: 4,25% | E29: 0.0425
B30: Fashion Bayi & Anak Lainnya | C30: Fashion Bayi & Anak Lainnya | D30: 9,00% | E30: 0.09
A31: Fashion Muslim | B31: Pakaian Muslim Wanita | C31: Baju Olahraga Muslim, Baju Renang Muslim | D31: 10,00%* | E31: 0.1
B32: Mukena & Perlengkapan Sholat | C32: Set Perlengkapan Sholat, Sajadah, Peci, Songkok & Kopiah, Mukena, Mukena Travel, Mukena & Perlengkapan Sholat Lainnya | D32: 8,25% | E32: 0.0825
B33: Outerwear | C33: Rompi, Jaket, Mantel, Cardigan, Outerwear Lainnya | E33: 0.0825
B34: Pakaian Muslim Anak | C34: Mukena, Hijab, Pakaian & Set Muslim, Pakaian Muslim Anak Perempuan Lainnya, Pakaian Muslim Anak Laki-Laki, Pakaian Muslim Anak Lainnya | E34: 0.0825
B35: Pakaian Muslim Pria | C35: Atasan, Gamis Pria, Celana, Sarung, Baju Melayu, Pakaian Muslim Pria Lainnya | E35: 0.0825
B36: Pakaian Muslim Wanita | C36: Khimar, Hijab Instan, Hijab Segi Empat, Pashmina, Ciput, Pin Hijab, Hijab Lainnya, Aksesoris Hijab Lainnya, Kaos Kaki, Handsock, Aksesoris Lainnya, Tunik, Kemeja, Blus, & Inner, Atasan Menyusui, Atasan Muslim Lainnya, Gamis, Abaya, Dress Menyusui, Kaftan, Baju Kelelawar, Baju Kurung, Set Baju Muslim, Jumpsuit, Dress Lainnya, Rok, Celana Panjang, Legging, Celana Palazzo, Bawahan Lainnya, Pakaian Muslim Wanita Lainnya | E36: 0.0825
B37: Set | C37: Set | E37: 0.0825
B38: Fashion Muslim Lainnya | C38: Fashion Muslim Lainnya | E38: 0.0825
A39: Jam Tangan | B39: Aksesoris Jam Tangan | C39: Strap, Alat Servis Jam Tangan, Pengait Jam Tangan, Baterai Jam Tangan, Kotak Jam Tangan, Aksesoris Jam Tangan lainnya | D39: 9,00% | E39: 0.09
B40: Jam Tangan Couple | C40: Jam Tangan Couple | E40: 0.09
B41: Jam Tangan Pria | C41: Jam Tangan Pria | E41: 0.09
...

Sheet Biaya Gratis Ongkir Xtra
B2: Biaya Produk Pre-Order
B3: Tidak Ikut | C3: 0
B4: Produk Pre-Order | C4: 0.03
B6: Biaya Promo Xtra
B7: Tidak Ikut | C7: 0
B8: Sebelum 11 Sept | C8: 0.02
B9: Setelah 11 Sept | C9: 0.045
B10: Promo Xtra+ | C10: 0.065
B12: Program Opsional Gratis Ongkir Xtra Ukuran Biasa & Khusus
B13: PROGRAM | C13: KATEGORI PRODUK | D13: PRODUK UKURAN BIASA
B14: Biaya Layanan Program Opsional Gratis Ongkir XTRA | C14: Ukuran Biasa - A | D14: 0.01
C15: Ukuran Biasa - B | D15: 0.02
C16: Ukuran Biasa - C | D16: 0.035
C17: Ukuran Biasa - D | D17: 0.055
C18: Ukuran Biasa - E | D18: 0.06
C19: Ukuran Biasa - F | D19: 0.065
C20: Ukuran Biasa - G | D20: 0.075
C21: Ukuran Biasa - H | D21: 0.08
D22: Rp40.000 per kuantitas produk
D23: PRODUK UKURAN KHUSUS
C24: Ukuran Khusus - A | D24: 0.025
C25: Ukuran Khusus - B | D25: 0.035
C26: Ukuran Khusus - C | D26: 0.05
C27: Ukuran Khusus - D | D27: 0.07
C28: Ukuran Khusus - E | D28: 0.075
C29: Ukuran Khusus - F | D29: 0.08
C30: Ukuran Khusus - G | D30: 0.09
C31: Ukuran Khusus - H | D31: 0.095
D32: Rp60.000 per kuantitas produk
B34: Cek Barang Masuk Kategori Apa Disini | C34: https://seller.shopee.co.id/edu/article/24877
B35: Cek Apa itu Ukuran Khsuus Disini | C35: https://seller.shopee.co.id/edu/article/26487

Sheet Kalkulator Biaya Layanan (Baca 
A1: WAJIB BACA PANDUAN CARA PAKAI AGAR FILE BISA DIGUNAKAN (CARA BUAT SALINAN/ MAKE A COPY)
B2: Saran/ Kendala Penggunaan: WA Admin (085156685865)
B3: *Hanya Ubah Kotak Berwarna Hijau
B4: Kalkulator Biaya Admin & Layanan Shopee
B5: Harga Produk Penjual | C5: Atribut | D5: Rupiah | F5: Panduan Isi
B6: Harga Pokok Penjualan (HPP) | C6: Input Harga Modal Produk -> | E6: 66000 | F6: (isi harga modal, jika ada biaya packing masukin juga)
B7: Target Harga Jual (Rp) | C7: Input Harga Jual Produk -> | E7: 125000 | F7: (isi total dari HPP + target cuan)
B8: Diskon Penjual (Rp) | C8: Input Diskon Dibuat -> | E8: 0 | F8: (kosongkan jika tidak ada)
B9: Harga Produk Final | C9: Harga yang Dibayar Pembeli -> | E9: =E7-E8 -> 125000 | F9: (jangan ubah kolom ini)
B12: Biaya Administrasi & Layanan | C12: Atribut | D12: Persentase | E12: Rupiah | F12: Panduan Isi
B13: Biaya Administrasi per Kategori | C13: Alat & Aksesoris Musik | D13: {=INDEX('Biaya Administrasi'!E:E, MATCH(C13, 'Biaya Administrasi'!B:B, 0))} -> 0.095 | E13: =$E$9*$D$13 -> 11875 | F13: (pilih kategori)
B14: Gratis Ongkir Xtra (Kategori) Update per 5 Februari 2026 | C14: Ukuran Biasa - E | D14: {=INDEX('Biaya Gratis Ongkir Xtra'!D:D, MATCH(C14, 'Biaya Gratis Ongkir Xtra'!C:C, 0))} -> 0.06 | E14: =MIN( $E$9*$D$14, IF(LEFT(C14,12)="Ukuran Biasa", 40000, IF(LEFT(C14,13)="Ukuran Khusus", 60000, NA() ) ) ) -> 7500 | F14: (Ukuran Biasa 40k maks. Ukuran Khusus 60k maks.)
B15: Promo Xtra | C15: Setelah 11 Sept | D15: {=INDEX('Biaya Gratis Ongkir Xtra'!C7:C10, MATCH(C15, 'Biaya Gratis Ongkir Xtra'!B7:B10, 0))} -> 0.045 | E15: =MIN( $E$9*$D$15, IF(C15="Promo Xtra+",80000,60000) ) -> 5625 | F15: (Promo Xtra 60k maks. Promo Xtra+ 80k maks.)
B16: Biaya Proses Pesanan | C16: Biaya Fix (20 Juli 2025) | D16: - | E16: 1250 | F16: (jangan ubah kolom ini)
B17: Biaya Produk Pre-Order | C17: Tidak Ikut | D17: {=INDEX('Biaya Gratis Ongkir Xtra'!C3:C4, MATCH(C17, 'Biaya Gratis Ongkir Xtra'!B3:B4, 0))} -> 0 | E17: =$E$9*$D$17 -> 0 | F17: (pilih ikut/ tidak ikut jika prorduk pre order)
B18: Total Biaya Administrasi & Layanan | D18: =(E18/E9) -> 0.21 | E18: =$E$14+$E$15+$E$13+$E$16+E17 -> 26250 | F18: (jangan ubah kolom ini)
B19: Dana Diterima Penjual Star/ Star+ > 50 Pesanan | E19: =$E$9-$E$18 -> 98750 | F19: (ini adalah total untuk penjual non star dan star >50 pesanan)
B21: Komisi Afiliasi | C21: Atribut | D21: Persentase | E21: Rupiah | F21: Panduan Isi
B22: Persentase Komisi Afiliasi | C22: Input Persentase Biaya Komisi -> | D22: 0 | E22: =MIN($E$9*$D$22) -> 0 | F22: [biaya afiliasi= (harga produk- diskon penjual)* biaya afiliasi]
B23: Dana Diterima Penjual (Setelah Afiliasi) | E23: =$E$19-$E$22 -> 98750 | F23: (ini adalah total dana diterima untuk penjual, setelah afiliasi)
B25: Margin Setelah Fee Admin | D25: Persentase | E25: Rupiah | F25: Panduan Isi
B26: Biaya Pajak Penghasilan <=4,8M/ Tahun | C26: 0.5% * Omzet Bruto | D26: 0.005 | E26: =E19*D26 -> 493.75 | F26: (ini adalah biaya pajak untuk penjual star)
B27: Margin Star/ Star+ Seller >50 | D27: =(E23-E6)/E23 -> 0.33164557 | E27: =E19-E6-E22 -> 32750 | F27: (ini adalah keuntungan kotor untuk penjual dan star >50 pesanan)
B29: Rekomendasi Harga Jual | F29: Panduan Isi
B30: =E9+(E9*D18)+E22+E26 -> 151743.75 | F30: (target harga jual + admin & layanan + pajak)

Sheet Dashboard Harga
C1: WAJIB BACA PANDUAN CARA PAKAI AGAR FILE BISA DIGUNAKAN (CARA BUAT SALINAN/ MAKE A COPY)
C5: Atribut Produk Penjual (Kolom Isian) | I5: Kategori Barang (Kolom Isian) | N5: Biaya Administrasi & Layanan (Otomatis) | X5: Rangkuman Biaya (Otomatis)
B6: Nama Produk | C6: Harga Pokok Penjualan (HPP) | D6: Ambil Untung (Rp) | E6: Diskon Penjual (Rp) | F6: Persentase Afiliasei | G6: Harga Produk Final | I6: Biaya Administrasi | J6: Gratis Ongkir Xtra | K6: Promo Xtra | L6: Biaya Produk Pre-Order | N6: Biaya Administrasi | P6: Gratis Ongkir Xtra | R6: Promo Xtra | T6: Biaya Proses Pesanan | U6: Biaya Produk Pre-Order | X6: Total Biaya Administrasi & Layanan | Y6: Besaran Affiliate | Z6: Dana Diterima Penjual Setelah Admin | AA6: Biaya Pajak Penghasilan <=4,8M/ Tahun | AB6: Profit Setelah Admin | AC6: Rekomendasi Harga Jual
C7: (isi harga modal, jika ada biaya packing masukin juga) | D7: (isi total dari HPP + target cuan) | E7: (kosongkan jika tidak ada) | G7: (jangan ubah kolom ini) | I7: (pilih kategori) | J7: (Ukuran Biasa 40k maks. Ukuran Khusus 60k maks.) | K7: (Promo Xtra 60k maks. Promo Xtra+ 80k maks.) | L7: (pilih ikut/ tidak ikut jika prorduk pre order) | N7: Persen | O7: Nominal | P7: Persen | Q7: Nominal | R7: Persen | S7: Nominal | T7: (jangan ubah kolom ini) | U7: Persen | V7: Nominal | X7: (jangan ubah kolom ini) | Y7: (jangan ubah kolom ini) | Z7: (ini adalah total untuk penjual non star dan star >50 pesanan) | AA7: (ini adalah biaya pajak untuk penjual star) | AB7: (ini adalah keuntungan kotor untuk penjual dan star >50 pesanan) | AC7: (target harga jual + admin & layanan + pajak)
B8: Design Sablon A | C8: 100000 | D8: 25000 | F8: 0.1 | G8: =if(C8=0,"",(C8+D8-E8)) -> 125000 | I8: Pakaian Pria Lainnya | J8: Ukuran Biasa - A | K8: Promo Xtra+ | L8: Tidak Ikut | N8: {=if(C8=0,"",INDEX('Biaya Administrasi'!E:E, MATCH(I8, 'Biaya Administrasi'!B:B, 0)))} -> 0.0825 | O8: =if(C8=0,"",G8*N8) -> 10312.5 | P8: {=if(J8=0,"",INDEX('Biaya Gratis Ongkir Xtra'!D:D, MATCH(J8, 'Biaya Gratis Ongkir Xtra'!C:C, 0)))} -> 0.01 | Q8: =if(J8=0,"",MIN( P8*G8, IF(LEFT(J8,12)="Ukuran Biasa", 40000, IF(LEFT(J8,13)="Ukuran Khusus", 60000, NA() ) ) )) -> 1250 | R8: {=if(K8=0,"",INDEX('Biaya Gratis Ongkir Xtra'!$C$7:$C$10, MATCH(K8, 'Biaya Gratis Ongkir Xtra'!$B$7:$B$10, 0)))} -> 0.065 | S8: =if(K8=0,"",MIN( R8*G8, IF(K8="Promo Xtra+",80000,60000) )) -> 8125 | T8: =if(C8=0,"",1250) -> 1250 | U8: {=if(C8=0,"",INDEX('Biaya Gratis Ongkir Xtra'!$C$3:$C$4, MATCH(L8, 'Biaya Gratis Ongkir Xtra'!$B$3:$B$4, 0)))} -> 0 | V8: =if(C8=0,"",U8*G8) -> 0 | X8: =if(C8=0,"",O8+Q8+S8+T8+V8) -> 20937.5 | Y8: =if(C8=0,"",F8*G8) -> 12500 | Z8: =if(C8=0,"",G8-X8) -> 104062.5 | AA8: =if(C8=0,"",Z8*0.5%) -> 520.3125 | AB8: =if(C8=0,"",Z8-C8) -> 4062.5 | AC8: =if(C8=0,"",G8+X8+AA8+Y8) -> 158957.81
B9: Design Sablon B | C9: 100000 | D9: 63933 | F9: 0.1 | G9: =if(C9=0,"",(C9+D9-E9)) -> 163933 | I9: Pakaian Pria Lainnya | J9: Ukuran Biasa - C | K9: Promo Xtra+ | L9: Tidak Ikut | N9: {=if(C9=0,"",INDEX('Biaya Administrasi'!E:E, MATCH(I9, 'Biaya Administrasi'!B:B, 0)))} -> 0.0825 | O9: =if(C9=0,"",G9*N9) -> 13524.472 | P9: {=if(J9=0,"",INDEX('Biaya Gratis Ongkir Xtra'!D:D, MATCH(J9, 'Biaya Gratis Ongkir Xtra'!C:C, 0)))} -> 0.035 | Q9: =if(J9=0,"",MIN( P9*G9, IF(LEFT(J9,12)="Ukuran Biasa", 40000, IF(LEFT(J9,13)="Ukuran Khusus", 60000, NA() ) ) )) -> 5737.655 | R9: {=if(K9=0,"",INDEX('Biaya Gratis Ongkir Xtra'!$C$7:$C$10, MATCH(K9, 'Biaya Gratis Ongkir Xtra'!$B$7:$B$10, 0)))} -> 0.065 | S9: =if(K9=0,"",MIN( R9*G9, IF(K9="Promo Xtra+",80000,60000) )) -> 10655.645 | T9: =if(C9=0,"",1250) -> 1250 | U9: {=if(C9=0,"",INDEX('Biaya Gratis Ongkir Xtra'!$C$3:$C$4, MATCH(L9, 'Biaya Gratis Ongkir Xtra'!$B$3:$B$4, 0)))} -> 0 | V9: =if(C9=0,"",U9*G9) -> 0 | X9: =if(C9=0,"",O9+Q9+S9+T9+V9) -> 31167.772 | Y9: =if(C9=0,"",F9*G9) -> 16393.3 | Z9: =if(C9=0,"",G9-X9) -> 132765.23 | AA9: =if(C9=0,"",Z9*0.5%) -> 663.82614 | AB9: =if(C9=0,"",Z9-C9) -> 32765.228 | AC9: =if(C9=0,"",G9+X9+AA9+Y9) -> 212157.9
B10: Kipas | C10: 150000 | D10: 30000 | F10: 0.1 | G10: =if(C10=0,"",(C10+D10-E10)) -> 180000 | I10: Elektronik Lainnya | J10: Ukuran Biasa - C | K10: Setelah 11 Sept | L10: Tidak Ikut | N10: {=if(C10=0,"",INDEX('Biaya Administrasi'!E:E, MATCH(I10, 'Biaya Administrasi'!B:B, 0)))} -> 0.09 | O10: =if(C10=0,"",G10*N10) -> 16200 | P10: {=if(J10=0,"",INDEX('Biaya Gratis Ongkir Xtra'!D:D, MATCH(J10, 'Biaya Gratis Ongkir Xtra'!C:C, 0)))} -> 0.035 | Q10: =if(J10=0,"",MIN( P10*G10, IF(LEFT(J10,12)="Ukuran Biasa", 40000, IF(LEFT(J10,13)="Ukuran Khusus", 60000, NA() ) ) )) -> 6300 | R10: {=if(K10=0,"",INDEX('Biaya Gratis Ongkir Xtra'!$C$7:$C$10, MATCH(K10, 'Biaya Gratis Ongkir Xtra'!$B$7:$B$10, 0)))} -> 0.045 | S10: =if(K10=0,"",MIN( R10*G10, IF(K10="Promo Xtra+",80000,60000) )) -> 8100 | T10: =if(C10=0,"",1250) -> 1250 | U10: {=if(C10=0,"",INDEX('Biaya Gratis Ongkir Xtra'!$C$3:$C$4, MATCH(L10, 'Biaya Gratis Ongkir Xtra'!$B$3:$B$4, 0)))} -> 0 | V10: =if(C10=0,"",U10*G10) -> 0 | X10: =if(C10=0,"",O10+Q10+S10+T10+V10) -> 31850 | Y10: =if(C10=0,"",F10*G10) -> 18000 | Z10: =if(C10=0,"",G10-X10) -> 148150 | AA10: =if(C10=0,"",Z10*0.5%) -> 740.75 | AB10: =if(C10=0,"",Z10-C10) -> -1850 | AC10: =if(C10=0,"",G10+X10+AA10+Y10) -> 230590.75
B11: HP | C11: 1600000 | D11: 200000 | F11: 0.1 | G11: =if(C11=0,"",(C11+D11-E11)) -> 1800000 | I11: Handphone | J11: Ukuran Khusus - C | K11: Promo Xtra+ | L11: Tidak Ikut | N11: {=if(C11=0,"",INDEX('Biaya Administrasi'!E:E, MATCH(I11, 'Biaya Administrasi'!B:B, 0)))} -> 0.0525 | O11: =if(C11=0,"",G11*N11) -> 94500 | P11: {=if(J11=0,"",INDEX('Biaya Gratis Ongkir Xtra'!D:D, MATCH(J11, 'Biaya Gratis Ongkir Xtra'!C:C, 0)))} -> 0.05 | Q11: =if(J11=0,"",MIN( P11*G11, IF(LEFT(J11,12)="Ukuran Biasa", 40000, IF(LEFT(J11,13)="Ukuran Khusus", 60000, NA() ) ) )) -> 60000 | R11: {=if(K11=0,"",INDEX('Biaya Gratis Ongkir Xtra'!$C$7:$C$10, MATCH(K11, 'Biaya Gratis Ongkir Xtra'!$B$7:$B$10, 0)))} -> 0.065 | S11: =if(K11=0,"",MIN( R11*G11, IF(K11="Promo Xtra+",80000,60000) )) -> 80000 | T11: =if(C11=0,"",1250) -> 1250 | U11: {=if(C11=0,"",INDEX('Biaya Gratis Ongkir Xtra'!$C$3:$C$4, MATCH(L11, 'Biaya Gratis Ongkir Xtra'!$B$3:$B$4, 0)))} -> 0 | V11: =if(C11=0,"",U11*G11) -> 0 | X11: =if(C11=0,"",O11+Q11+S11+T11+V11) -> 235750 | Y11: =if(C11=0,"",F11*G11) -> 180000 | Z11: =if(C11=0,"",G11-X11) -> 1564250 | AA11: =if(C11=0,"",Z11*0.5%) -> 7821.25 | AB11: =if(C11=0,"",Z11-C11) -> -35750 | AC11: =if(C11=0,"",G11+X11+AA11+Y11) -> 2223571.2
B12: Sosis | C12: 26672 | G12: =if(C12=0,"",(C12+D12-E12)) -> 26672 | I12: Makanan Ringan | J12: Ukuran Biasa - E | K12: Setelah 11 Sept | L12: Tidak Ikut | N12: {=if(C12=0,"",INDEX('Biaya Administrasi'!E:E, MATCH(I12, 'Biaya Administrasi'!B:B, 0)))} -> 0.1 | O12: =if(C12=0,"",G12*N12) -> 2667.2 | P12: {=if(J12=0,"",INDEX('Biaya Gratis Ongkir Xtra'!D:D, MATCH(J12, 'Biaya Gratis Ongkir Xtra'!C:C, 0)))} -> 0.06 | Q12: =if(J12=0,"",MIN( P12*G12, IF(LEFT(J12,12)="Ukuran Biasa", 40000, IF(LEFT(J12,13)="Ukuran Khusus", 60000, NA() ) ) )) -> 1600.32 | R12: {=if(K12=0,"",INDEX('Biaya Gratis Ongkir Xtra'!$C$7:$C$10, MATCH(K12, 'Biaya Gratis Ongkir Xtra'!$B$7:$B$10, 0)))} -> 0.045 | S12: =if(K12=0,"",MIN( R12*G12, IF(K12="Promo Xtra+",80000,60000) )) -> 1200.24 | U12: {=if(C12=0,"",INDEX('Biaya Gratis Ongkir Xtra'!$C$3:$C$4, MATCH(L12, 'Biaya Gratis Ongkir Xtra'!$B$3:$B$4, 0)))} -> 0 | V12: =if(C12=0,"",U12*G12) -> 0 | X12: =if(C12=0,"",O12+Q12+S12+T12+V12) -> 5467.76 | Y12: =if(C12=0,"",F12*G12) -> 0 | Z12: =if(C12=0,"",G12-X12) -> 21204.24 | AA12: =if(C12=0,"",Z12*0.5%) -> 106.0212 | AB12: =if(C12=0,"",Z12-C12) -> -5467.76 | AC12: =if(C12=0,"",G12+X12+AA12+Y12) -> 32245.781
B13: Rice Cooker | C13: 273575 | E13: 3000 | G13: =if(C13=0,"",(C13+D13-E13)) -> 270575 | I13: Perangkat Dapur | J13: Ukuran Khusus - D | K13: Setelah 11 Sept | L13: Tidak Ikut | N13: {=if(C13=0,"",INDEX('Biaya Administrasi'!E:E, MATCH(I13, 'Biaya Administrasi'!B:B, 0)))} -> 0.065 | O13: =if(C13=0,"",G13*N13) -> 17587.375 | P13: {=if(J13=0,"",INDEX('Biaya Gratis Ongkir Xtra'!D:D, MATCH(J13, 'Biaya Gratis Ongkir Xtra'!C:C, 0)))} -> 0.07 | Q13: =if(J13=0,"",MIN( P13*G13, IF(LEFT(J13,12)="Ukuran Biasa", 40000, IF(LEFT(J13,13)="Ukuran Khusus", 60000, NA() ) ) )) -> 18940.25 | R13: {=if(K13=0,"",INDEX('Biaya Gratis Ongkir Xtra'!$C$7:$C$10, MATCH(K13, 'Biaya Gratis Ongkir Xtra'!$B$7:$B$10, 0)))} -> 0.045 | S13: =if(K13=0,"",MIN( R13*G13, IF(K13="Promo Xtra+",80000,60000) )) -> 12175.875 | T13: =if(C13=0,"",1250) -> 1250 | U13: {=if(C13=0,"",INDEX('Biaya Gratis Ongkir Xtra'!$C$3:$C$4, MATCH(L13, 'Biaya Gratis Ongkir Xtra'!$B$3:$B$4, 0)))} -> 0 | V13: =if(C13=0,"",U13*G13) -> 0 | X13: =if(C13=0,"",O13+Q13+S13+T13+V13) -> 49953.5 | Y13: =if(C13=0,"",F13*G13) -> 0 | Z13: =if(C13=0,"",G13-X13) -> 220621.5 | AA13: =if(C13=0,"",Z13*0.5%) -> 1103.1075 | AB13: =if(C13=0,"",Z13-C13) -> -52953.5 | AC13: =if(C13=0,"",G13+X13+AA13+Y13) -> 321631.61
B14: Blender | C14: 265000 | D14: 0 | E14: 3000 | G14: =if(C14=0,"",(C14+D14-E14)) -> 262000 | I14: Perangkat Dapur | J14: Ukuran Biasa - D | K14: Setelah 11 Sept | L14: Tidak Ikut | N14: {=if(C14=0,"",INDEX('Biaya Administrasi'!E:E, MATCH(I14, 'Biaya Administrasi'!B:B, 0)))} -> 0.065 | O14: =if(C14=0,"",G14*N14) -> 17030 | P14: {=if(J14=0,"",INDEX('Biaya Gratis Ongkir Xtra'!D:D, MATCH(J14, 'Biaya Gratis Ongkir Xtra'!C:C, 0)))} -> 0.055 | Q14: =if(J14=0,"",MIN( P14*G14, IF(LEFT(J14,12)="Ukuran Biasa", 40000, IF(LEFT(J14,13)="Ukuran Khusus", 60000, NA() ) ) )) -> 14410 | R14: {=if(K14=0,"",INDEX('Biaya Gratis Ongkir Xtra'!$C$7:$C$10, MATCH(K14, 'Biaya Gratis Ongkir Xtra'!$B$7:$B$10, 0)))} -> 0.045 | S14: =if(K14=0,"",MIN( R14*G14, IF(K14="Promo Xtra+",80000,60000) )) -> 11790 | T14: =if(C14=0,"",1250) -> 1250 | U14: {=if(C14=0,"",INDEX('Biaya Gratis Ongkir Xtra'!$C$3:$C$4, MATCH(L14, 'Biaya Gratis Ongkir Xtra'!$B$3:$B$4, 0)))} -> 0 | V14: =if(C14=0,"",U14*G14) -> 0 | X14: =if(C14=0,"",O14+Q14+S14+T14+V14) -> 44480 | Y14: =if(C14=0,"",F14*G14) -> 0 | Z14: =if(C14=0,"",G14-X14) -> 217520 | AA14: =if(C14=0,"",Z14*0.5%) -> 1087.6 | AB14: =if(C14=0,"",Z14-C14) -> -47480 | AC14: =if(C14=0,"",G14+X14+AA14+Y14) -> 307567.6
C15: 265000 | D15: =44975+7421+1224+202+34+5+1 -> 53862 | G15: =if(C15=0,"",(C15+D15-E15)) -> 318862 | I15: Perangkat Dapur | J15: Ukuran Biasa - D | K15: Setelah 11 Sept | L15: Tidak Ikut | N15: {=if(C15=0,"",INDEX('Biaya Administrasi'!E:E, MATCH(I15, 'Biaya Administrasi'!B:B, 0)))} -> 0.065 | O15: =if(C15=0,"",G15*N15) -> 20726.03 | P15: {=if(J15=0,"",INDEX('Biaya Gratis Ongkir Xtra'!D:D, MATCH(J15, 'Biaya Gratis Ongkir Xtra'!C:C, 0)))} -> 0.055 | Q15: =if(J15=0,"",MIN( P15*G15, IF(LEFT(J15,12)="Ukuran Biasa", 40000, IF(LEFT(J15,13)="Ukuran Khusus", 60000, NA() ) ) )) -> 17537.41 | R15: {=if(K15=0,"",INDEX('Biaya Gratis Ongkir Xtra'!$C$7:$C$10, MATCH(K15, 'Biaya Gratis Ongkir Xtra'!$B$7:$B$10, 0)))} -> 0.045 | S15: =if(K15=0,"",MIN( R15*G15, IF(K15="Promo Xtra+",80000,60000) )) -> 14348.79 | T15: =if(C15=0,"",1250) -> 1250 | U15: {=if(C15=0,"",INDEX('Biaya Gratis Ongkir Xtra'!$C$3:$C$4, MATCH(L15, 'Biaya Gratis Ongkir Xtra'!$B$3:$B$4, 0)))} -> 0 | V15: =if(C15=0,"",U15*G15) -> 0 | X15: =if(C15=0,"",O15+Q15+S15+T15+V15) -> 53862.23 | Y15: =if(C15=0,"",F15*G15) -> 0 | Z15: =if(C15=0,"",G15-X15) -> 264999.77 | AA15: =if(C15=0,"",Z15*0.5%) -> 1324.9988 | AB15: =if(C15=0,"",Z15-C15) -> -0.23 | AC15: =if(C15=0,"",G15+X15+AA15+Y15) -> 374049.23
G16: =if(C16=0,"",(C16+D16-E16)) | N16: {=if(C16=0,"",INDEX('Biaya Administrasi'!E:E, MATCH(I16, 'Biaya Administrasi'!B:B, 0)))} | O16: =if(C16=0,"",G16*N16) | P16: {=if(J16=0,"",INDEX('Biaya Gratis Ongkir Xtra'!D:D, MATCH(J16, 'Biaya Gratis Ongkir Xtra'!C:C, 0)))} | Q16: =if(J16=0,"",MIN( P16*G16, IF(LEFT(J16,12)="Ukuran Biasa", 40000, IF(LEFT(J16,13)="Ukuran Khusus", 60000, NA() ) ) )) | R16: {=if(K16=0,"",INDEX('Biaya Gratis Ongkir Xtra'!$C$7:$C$10, MATCH(K16, 'Biaya Gratis Ongkir Xtra'!$B$7:$B$10, 0)))} | S16: =if(K16=0,"",MIN( R16*G16, IF(K16="Promo Xtra+",80000,60000) )) | T16: =if(C16=0,"",1250) | U16: {=if(C16=0,"",INDEX('Biaya Gratis Ongkir Xtra'!$C$3:$C$4, MATCH(L16, 'Biaya Gratis Ongkir Xtra'!$B$3:$B$4, 0)))} | V16: =if(C16=0,"",U16*G16) | X16: =if(C16=0,"",O16+Q16+S16+T16+V16) | Y16: =if(C16=0,"",F16*G16) | Z16: =if(C16=0,"",G16-X16) | AA16: =if(C16=0,"",Z16*0.5%) | AB16: =if(C16=0,"",Z16-C16) | AC16: =if(C16=0,"",G16+X16+AA16+Y16)
G17: =if(C17=0,"",(C17+D17-E17)) | N17: {=if(C17=0,"",INDEX('Biaya Administrasi'!E:E, MATCH(I17, 'Biaya Administrasi'!B:B, 0)))} | O17: =if(C17=0,"",G17*N17) | P17: {=if(J17=0,"",INDEX('Biaya Gratis Ongkir Xtra'!D:D, MATCH(J17, 'Biaya Gratis Ongkir Xtra'!C:C, 0)))} | Q17: =if(J17=0,"",MIN( P17*G17, IF(LEFT(J17,12)="Ukuran Biasa", 40000, IF(LEFT(J17,13)="Ukuran Khusus", 60000, NA() ) ) )) | R17: {=if(K17=0,"",INDEX('Biaya Gratis Ongkir Xtra'!$C$7:$C$10, MATCH(K17, 'Biaya Gratis Ongkir Xtra'!$B$7:$B$10, 0)))} | S17: =if(K17=0,"",MIN( R17*G17, IF(K17="Promo Xtra+",80000,60000) )) | T17: =if(C17=0,"",1250) | U17: {=if(C17=0,"",INDEX('Biaya Gratis Ongkir Xtra'!$C$3:$C$4, MATCH(L17, 'Biaya Gratis Ongkir Xtra'!$B$3:$B$4, 0)))} | V17: =if(C17=0,"",U17*G17) | X17: =if(C17=0,"",O17+Q17+S17+T17+V17) | Y17: =if(C17=0,"",F17*G17) | Z17: =if(C17=0,"",G17-X17) | AA17: =if(C17=0,"",Z17*0.5%) | AB17: =if(C17=0,"",Z17-C17) | AC17: =if(C17=0,"",G17+X17+AA17+Y17)
G18: =if(C18=0,"",(C18+D18-E18)) | N18: {=if(C18=0,"",INDEX('Biaya Administrasi'!E:E, MATCH(I18, 'Biaya Administrasi'!B:B, 0)))} | O18: =if(C18=0,"",G18*N18) | P18: {=if(J18=0,"",INDEX('Biaya Gratis Ongkir Xtra'!D:D, MATCH(J18, 'Biaya Gratis Ongkir Xtra'!C:C, 0)))} | Q18: =if(J18=0,"",MIN( P18*G18, IF(LEFT(J18,12)="Ukuran Biasa", 40000, IF(LEFT(J18,13)="Ukuran Khusus", 60000, NA() ) ) )) | R18: {=if(K18=0,"",INDEX('Biaya Gratis Ongkir Xtra'!$C$7:$C$10, MATCH(K18, 'Biaya Gratis Ongkir Xtra'!$B$7:$B$10, 0)))} | S18: =if(K18=0,"",MIN( R18*G18, IF(K18="Promo Xtra+",80000,60000) )) | T18: =if(C18=0,"",1250) | U18: {=if(C18=0,"",INDEX('Biaya Gratis Ongkir Xtra'!$C$3:$C$4, MATCH(L18, 'Biaya Gratis Ongkir Xtra'!$B$3:$B$4, 0)))} | V18: =if(C18=0,"",U18*G18) | X18: =if(C18=0,"",O18+Q18+S18+T18+V18) | Y18: =if(C18=0,"",F18*G18) | Z18: =if(C18=0,"",G18-X18) | AA18: =if(C18=0,"",Z18*0.5%) | AB18: =if(C18=0,"",Z18-C18) | AC18: =if(C18=0,"",G18+X18+AA18+Y18)
G19: =if(C19=0,"",(C19+D19-E19)) | N19: {=if(C19=0,"",INDEX('Biaya Administrasi'!E:E, MATCH(I19, 'Biaya Administrasi'!B:B, 0)))} | O19: =if(C19=0,"",G19*N19) | P19: {=if(J19=0,"",INDEX('Biaya Gratis Ongkir Xtra'!D:D, MATCH(J19, 'Biaya Gratis Ongkir Xtra'!C:C, 0)))} | Q19: =if(J19=0,"",MIN( P19*G19, IF(LEFT(J19,12)="Ukuran Biasa", 40000, IF(LEFT(J19,13)="Ukuran Khusus", 60000, NA() ) ) )) | R19: {=if(K19=0,"",INDEX('Biaya Gratis Ongkir Xtra'!$C$7:$C$10, MATCH(K19, 'Biaya Gratis Ongkir Xtra'!$B$7:$B$10, 0)))} | S19: =if(K19=0,"",MIN( R19*G19, IF(K19="Promo Xtra+",80000,60000) )) | T19: =if(C19=0,"",1250) | U19: {=if(C19=0,"",INDEX('Biaya Gratis Ongkir Xtra'!$C$3:$C$4, MATCH(L19, 'Biaya Gratis Ongkir Xtra'!$B$3:$B$4, 0)))} | V19: =if(C19=0,"",U19*G19) | X19: =if(C19=0,"",O19+Q19+S19+T19+V19) | Y19: =if(C19=0,"",F19*G19) | Z19: =if(C19=0,"",G19-X19) | AA19: =if(C19=0,"",Z19*0.5%) | AB19: =if(C19=0,"",Z19-C19) | AC19: =if(C19=0,"",G19+X19+AA19+Y19)
G20: =if(C20=0,"",(C20+D20-E20)) | N20: {=if(C20=0,"",INDEX('Biaya Administrasi'!E:E, MATCH(I20, 'Biaya Administrasi'!B:B, 0)))} | O20: =if(C20=0,"",G20*N20) | P20: {=if(J20=0,"",INDEX('Biaya Gratis Ongkir Xtra'!D:D, MATCH(J20, 'Biaya Gratis Ongkir Xtra'!C:C, 0)))} | Q20: =if(J20=0,"",MIN( P20*G20, IF(LEFT(J20,12)="Ukuran Biasa", 40000, IF(LEFT(J20,13)="Ukuran Khusus", 60000, NA() ) ) )) | R20: {=if(K20=0,"",INDEX('Biaya Gratis Ongkir Xtra'!$C$7:$C$10, MATCH(K20, 'Biaya Gratis Ongkir Xtra'!$B$7:$B$10, 0)))} | S20: =if(K20=0,"",MIN( R20*G20, IF(K20="Promo Xtra+",80000,60000) )) | T20: =if(C20=0,"",1250) | U20: {=if(C20=0,"",INDEX('Biaya Gratis Ongkir Xtra'!$C$3:$C$4, MATCH(L20, 'Biaya Gratis Ongkir Xtra'!$B$3:$B$4, 0)))} | V20: =if(C20=0,"",U20*G20) | X20: =if(C20=0,"",O20+Q20+S20+T20+V20) | Y20: =if(C20=0,"",F20*G20) | Z20: =if(C20=0,"",G20-X20) | AA20: =if(C20=0,"",Z20*0.5%) | AB20: =if(C20=0,"",Z20-C20) | AC20: =if(C20=0,"",G20+X20+AA20+Y20)
G21: =if(C21=0,"",(C21+D21-E21)) | N21: {=if(C21=0,"",INDEX('Biaya Administrasi'!E:E, MATCH(I21, 'Biaya Administrasi'!B:B, 0)))} | O21: =if(C21=0,"",G21*N21) | P21: {=if(J21=0,"",INDEX('Biaya Gratis Ongkir Xtra'!D:D, MATCH(J21, 'Biaya Gratis Ongkir Xtra'!C:C, 0)))} | Q21: =if(J21=0,"",MIN( P21*G21, IF(LEFT(J21,12)="Ukuran Biasa", 40000, IF(LEFT(J21,13)="Ukuran Khusus", 60000, NA() ) ) )) | R21: {=if(K21=0,"",INDEX('Biaya Gratis Ongkir Xtra'!$C$7:$C$10, MATCH(K21, 'Biaya Gratis Ongkir Xtra'!$B$7:$B$10, 0)))} | S21: =if(K21=0,"",MIN( R21*G21, IF(K21="Promo Xtra+",80000,60000) )) | T21: =if(C21=0,"",1250) | U21: {=if(C21=0,"",INDEX('Biaya Gratis Ongkir Xtra'!$C$3:$C$4, MATCH(L21, 'Biaya Gratis Ongkir Xtra'!$B$3:$B$4, 0)))} | V21: =if(C21=0,"",U21*G21) | X21: =if(C21=0,"",O21+Q21+S21+T21+V21) | Y21: =if(C21=0,"",F21*G21) | Z21: =if(C21=0,"",G21-X21) | AA21: =if(C21=0,"",Z21*0.5%) | AB21: =if(C21=0,"",Z21-C21) | AC21: =if(C21=0,"",G21+X21+AA21+Y21)
G22: =if(C22=0,"",(C22+D22-E22)) | N22: {=if(C22=0,"",INDEX('Biaya Administrasi'!E:E, MATCH(I22, 'Biaya Administrasi'!B:B, 0)))} | O22: =if(C22=0,"",G22*N22) | P22: {=if(J22=0,"",INDEX('Biaya Gratis Ongkir Xtra'!D:D, MATCH(J22, 'Biaya Gratis Ongkir Xtra'!C:C, 0)))} | Q22: =if(J22=0,"",MIN( P22*G22, IF(LEFT(J22,12)="Ukuran Biasa", 40000, IF(LEFT(J22,13)="Ukuran Khusus", 60000, NA() ) ) )) | R22: {=if(K22=0,"",INDEX('Biaya Gratis Ongkir Xtra'!$C$7:$C$10, MATCH(K22, 'Biaya Gratis Ongkir Xtra'!$B$7:$B$10, 0)))} | S22: =if(K22=0,"",MIN( R22*G22, IF(K22="Promo Xtra+",80000,60000) )) | T22: =if(C22=0,"",1250) | U22: {=if(C22=0,"",INDEX('Biaya Gratis Ongkir Xtra'!$C$3:$C$4, MATCH(L22, 'Biaya Gratis Ongkir Xtra'!$B$3:$B$4, 0)))} | V22: =if(C22=0,"",U22*G22) | X22: =if(C22=0,"",O22+Q22+S22+T22+V22) | Y22: =if(C22=0,"",F22*G22) | Z22: =if(C22=0,"",G22-X22) | AA22: =if(C22=0,"",Z22*0.5%) | AB22: =if(C22=0,"",Z22-C22) | AC22: =if(C22=0,"",G22+X22+AA22+Y22)
G23: =if(C23=0,"",(C23+D23-E23)) | N23: {=if(C23=0,"",INDEX('Biaya Administrasi'!E:E, MATCH(I23, 'Biaya Administrasi'!B:B, 0)))} | O23: =if(C23=0,"",G23*N23) | P23: {=if(J23=0,"",INDEX('Biaya Gratis Ongkir Xtra'!D:D, MATCH(J23, 'Biaya Gratis Ongkir Xtra'!C:C, 0)))} | Q23: =if(J23=0,"",MIN( P23*G23, IF(LEFT(J23,12)="Ukuran Biasa", 40000, IF(LEFT(J23,13)="Ukuran Khusus", 60000, NA() ) ) )) | R23: {=if(K23=0,"",INDEX('Biaya Gratis Ongkir Xtra'!$C$7:$C$10, MATCH(K23, 'Biaya Gratis Ongkir Xtra'!$B$7:$B$10, 0)))} | S23: =if(K23=0,"",MIN( R23*G23, IF(K23="Promo Xtra+",80000,60000) )) | T23: =if(C23=0,"",1250) | U23: {=if(C23=0,"",INDEX('Biaya Gratis Ongkir Xtra'!$C$3:$C$4, MATCH(L23, 'Biaya Gratis Ongkir Xtra'!$B$3:$B$4, 0)))} | V23: =if(C23=0,"",U23*G23) | X23: =if(C23=0,"",O23+Q23+S23+T23+V23) | Y23: =if(C23=0,"",F23*G23) | Z23: =if(C23=0,"",G23-X23) | AA23: =if(C23=0,"",Z23*0.5%) | AB23: =if(C23=0,"",Z23-C23) | AC23: =if(C23=0,"",G23+X23+AA23+Y23)
G24: =if(C24=0,"",(C24+D24-E24)) | N24: {=if(C24=0,"",INDEX('Biaya Administrasi'!E:E, MATCH(I24, 'Biaya Administrasi'!B:B, 0)))} | O24: =if(C24=0,"",G24*N24) | P24: {=if(J24=0,"",INDEX('Biaya Gratis Ongkir Xtra'!D:D, MATCH(J24, 'Biaya Gratis Ongkir Xtra'!C:C, 0)))} | Q24: =if(J24=0,"",MIN( P24*G24, IF(LEFT(J24,12)="Ukuran Biasa", 40000, IF(LEFT(J24,13)="Ukuran Khusus", 60000, NA() ) ) )) | R24: {=if(K24=0,"",INDEX('Biaya Gratis Ongkir Xtra'!$C$7:$C$10, MATCH(K24, 'Biaya Gratis Ongkir Xtra'!$B$7:$B$10, 0)))} | S24: =if(K24=0,"",MIN( R24*G24, IF(K24="Promo Xtra+",80000,60000) )) | T24: =if(C24=0,"",1250) | U24: {=if(C24=0,"",INDEX('Biaya Gratis Ongkir Xtra'!$C$3:$C$4, MATCH(L24, 'Biaya Gratis Ongkir Xtra'!$B$3:$B$4, 0)))} | V24: =if(C24=0,"",U24*G24) | X24: =if(C24=0,"",O24+Q24+S24+T24+V24) | Y24: =if(C24=0,"",F24*G24) | Z24: =if(C24=0,"",G24-X24) | AA24: =if(C24=0,"",Z24*0.5%) | AB24: =if(C24=0,"",Z24-C24) | AC24: =if(C24=0,"",G24+X24+AA24+Y24)
G25: =if(C25=0,"",(C25+D25-E25)) | N25: {=if(C25=0,"",INDEX('Biaya Administrasi'!E:E, MATCH(I25, 'Biaya Administrasi'!B:B, 0)))} | O25: =if(C25=0,"",G25*N25) | P25: {=if(J25=0,"",INDEX('Biaya Gratis Ongkir Xtra'!D:D, MATCH(J25, 'Biaya Gratis Ongkir Xtra'!C:C, 0)))} | Q25: =if(J25=0,"",MIN( P25*G25, IF(LEFT(J25,12)="Ukuran Biasa", 40000, IF(LEFT(J25,13)="Ukuran Khusus", 60000, NA() ) ) )) | R25: {=if(K25=0,"",INDEX('Biaya Gratis Ongkir Xtra'!$C$7:$C$10, MATCH(K25, 'Biaya Gratis Ongkir Xtra'!$B$7:$B$10, 0)))} | S25: =if(K25=0,"",MIN( R25*G25, IF(K25="Promo Xtra+",80000,60000) )) | T25: =if(C25=0,"",1250) | U25: {=if(C25=0,"",INDEX('Biaya Gratis Ongkir Xtra'!$C$3:$C$4, MATCH(L25, 'Biaya Gratis Ongkir Xtra'!$B$3:$B$4, 0)))} | V25: =if(C25=0,"",U25*G25) | X25: =if(C25=0,"",O25+Q25+S25+T25+V25) | Y25: =if(C25=0,"",F25*G25) | Z25: =if(C25=0,"",G25-X25) | AA25: =if(C25=0,"",Z25*0.5%) | AB25: =if(C25=0,"",Z25-C25) | AC25: =if(C25=0,"",G25+X25+AA25+Y25)
G26: =if(C26=0,"",(C26+D26-E26)) | N26: {=if(C26=0,"",INDEX('Biaya Administrasi'!E:E, MATCH(I26, 'Biaya Administrasi'!B:B, 0)))} | O26: =if(C26=0,"",G26*N26) | P26: {=if(J26=0,"",INDEX('Biaya Gratis Ongkir Xtra'!D:D, MATCH(J26, 'Biaya Gratis Ongkir Xtra'!C:C, 0)))} | Q26: =if(J26=0,"",MIN( P26*G26, IF(LEFT(J26,12)="Ukuran Biasa", 40000, IF(LEFT(J26,13)="Ukuran Khusus", 60000, NA() ) ) )) | R26: {=if(K26=0,"",INDEX('Biaya Gratis Ongkir Xtra'!$C$7:$C$10, MATCH(K26, 'Biaya Gratis Ongkir Xtra'!$B$7:$B$10, 0)))} | S26: =if(K26=0,"",MIN( R26*G26, IF(K26="Promo Xtra+",80000,60000) )) | T26: =if(C26=0,"",1250) | U26: {=if(C26=0,"",INDEX('Biaya Gratis Ongkir Xtra'!$C$3:$C$4, MATCH(L26, 'Biaya Gratis Ongkir Xtra'!$B$3:$B$4, 0)))} | V26: =if(C26=0,"",U26*G26) | X26: =if(C26=0,"",O26+Q26+S26+T26+V26) | Y26: =if(C26=0,"",F26*G26) | Z26: =if(C26=0,"",G26-X26) | AA26: =if(C26=0,"",Z26*0.5%) | AB26: =if(C26=0,"",Z26-C26) | AC26: =if(C26=0,"",G26+X26+AA26+Y26)
G27: =if(C27=0,"",(C27+D27-E27)) | N27: {=if(C27=0,"",INDEX('Biaya Administrasi'!E:E, MATCH(I27, 'Biaya Administrasi'!B:B, 0)))} | O27: =if(C27=0,"",G27*N27) | P27: {=if(J27=0,"",INDEX('Biaya Gratis Ongkir Xtra'!D:D, MATCH(J27, 'Biaya Gratis Ongkir Xtra'!C:C, 0)))} | Q27: =if(J27=0,"",MIN( P27*G27, IF(LEFT(J27,12)="Ukuran Biasa", 40000, IF(LEFT(J27,13)="Ukuran Khusus", 60000, NA() ) ) )) | R27: {=if(K27=0,"",INDEX('Biaya Gratis Ongkir Xtra'!$C$7:$C$10, MATCH(K27, 'Biaya Gratis Ongkir Xtra'!$B$7:$B$10, 0)))} | S27: =if(K27=0,"",MIN( R27*G27, IF(K27="Promo Xtra+",80000,60000) )) | T27: =if(C27=0,"",1250) | U27: {=if(C27=0,"",INDEX('Biaya Gratis Ongkir Xtra'!$C$3:$C$4, MATCH(L27, 'Biaya Gratis Ongkir Xtra'!$B$3:$B$4, 0)))} | V27: =if(C27=0,"",U27*G27) | X27: =if(C27=0,"",O27+Q27+S27+T27+V27) | Y27: =if(C27=0,"",F27*G27) | Z27: =if(C27=0,"",G27-X27) | AA27: =if(C27=0,"",Z27*0.5%) | AB27: =if(C27=0,"",Z27-C27) | AC27: =if(C27=0,"",G27+X27+AA27+Y27)
... G303: =if(C303=0,"",(C303+D303-E303)) | N303: {=if(C303=0,"",INDEX('Biaya Administrasi'!E:E, MATCH(I303, 'Biaya Administrasi'!B:B, 0)))} | O303: =if(C303=0,"",G303*N303) | P303: {=if(J303=0,"",INDEX('Biaya Gratis Ongkir Xtra'!D:D, MATCH(J303, 'Biaya Gratis Ongkir Xtra'!C:C, 0)))} | Q303: =if(J303=0,"",MIN( P303*G303, IF(LEFT(J303,12)="Ukuran Biasa", 40000, IF(LEFT(J303,13)="Ukuran Khusus", 60000, NA() ) ) )) | R303: {=if(K303=0,"",INDEX('Biaya Gratis Ongkir Xtra'!$C$7:$C$10, MATCH(K303, 'Biaya Gratis Ongkir Xtra'!$B$7:$B$10, 0)))} | S303: =if(K303=0,"",MIN( R303*G303, IF(K303="Promo Xtra+",80000,60000) )) | T303: =if(C303=0,"",1250) | U303: {=if(C303=0,"",INDEX('Biaya Gratis Ongkir Xtra'!$C$3:$C$4, MATCH(L303, 'Biaya Gratis Ongkir Xtra'!$B$3:$B$4, 0)))} | V303: =if(C303=0,"",U303*G303) | X303: =if(C303=0,"",O303+Q303+S303+T303+V303) | Y303: =if(C303=0,"",F303*G303) | Z303: =if(C303=0,"",G303-X303) | AA303: =if(C303=0,"",Z303*0.5%) | AB303: =if(C303=0,"",Z303-C303) | AC303: =if(C303=0,"",G303+X303+AA303+Y303)
